2025-07-24 20:32:44,157 | DEBUG | connectionpool.py:1049 | Starting new HTTPS connection (1): example.com:443
2025-07-24 20:32:48,801 | DEBUG | connectionpool.py:544 | https://example.com:443 "GET /subscription.txt HTTP/1.1" 404 1256
2025-07-24 20:32:48,804 | INFO | vpn_manager.py:22 | Fetched 0 VPN servers
2025-07-24 20:35:08,153 | DEBUG | connectionpool.py:1049 | Starting new HTTPS connection (1): example.com:443
2025-07-24 20:35:09,152 | DEBUG | connectionpool.py:544 | https://example.com:443 "GET /subscription.txt HTTP/1.1" 404 1256
2025-07-24 20:35:09,154 | INFO | vpn_manager.py:22 | Fetched 0 VPN servers
2025-07-24 20:35:09,199 | DEBUG | proactor_events.py:633 | Using proactor: IocpProactor
2025-07-24 20:38:00,499 | DEBUG | connectionpool.py:1049 | Starting new HTTPS connection (1): example.com:443
2025-07-24 20:38:04,092 | DEBUG | connectionpool.py:544 | https://example.com:443 "GET /subscription.txt HTTP/1.1" 404 1256
2025-07-24 20:38:04,094 | INFO | vpn_manager.py:22 | Fetched 0 VPN servers
2025-07-24 20:41:26,585 | DEBUG | connectionpool.py:1049 | Starting new HTTPS connection (1): example.com:443
2025-07-24 20:41:27,742 | DEBUG | connectionpool.py:544 | https://example.com:443 "GET /subscription.txt HTTP/1.1" 404 1256
2025-07-24 20:41:27,744 | INFO | vpn_manager.py:22 | Fetched 0 VPN servers
2025-07-24 20:41:27,782 | DEBUG | proactor_events.py:633 | Using proactor: IocpProactor
2025-07-24 20:41:27,860 | INFO | dash.py:2340 | Dash is running on http://0.0.0.0:8050/

2025-07-24 20:41:28,767 | INFO | _internal.py:97 | [31m[1mWARNING: This is a development server. Do not use it in a production deployment. Use a production WSGI server instead.[0m
 * Running on all addresses (0.0.0.0)
 * Running on http://127.0.0.1:8050
 * Running on http://192.168.1.80:8050
2025-07-24 20:41:28,768 | INFO | _internal.py:97 | [33mPress CTRL+C to quit[0m
2025-07-24 20:41:41,643 | INFO | _internal.py:97 | 127.0.0.1 - - [24/Jul/2025 20:41:41] "GET / HTTP/1.1" 200 -
2025-07-24 20:41:41,717 | INFO | _internal.py:97 | 127.0.0.1 - - [24/Jul/2025 20:41:41] "GET /_dash-component-suites/dash/deps/prop-types@15.v3_1_1m1753374100.8.1.min.js HTTP/1.1" 200 -
2025-07-24 20:41:41,720 | INFO | _internal.py:97 | 127.0.0.1 - - [24/Jul/2025 20:41:41] "GET /_dash-component-suites/dash/deps/react@18.v3_1_1m1753374100.3.1.min.js HTTP/1.1" 200 -
2025-07-24 20:41:41,769 | INFO | _internal.py:97 | 127.0.0.1 - - [24/Jul/2025 20:41:41] "GET /_dash-component-suites/dash/deps/polyfill@7.v3_1_1m1753374100.12.1.min.js HTTP/1.1" 200 -
2025-07-24 20:41:41,799 | INFO | _internal.py:97 | 127.0.0.1 - - [24/Jul/2025 20:41:41] "GET /_dash-component-suites/dash/deps/react-dom@18.v3_1_1m1753374100.3.1.min.js HTTP/1.1" 200 -
2025-07-24 20:41:41,819 | INFO | _internal.py:97 | 127.0.0.1 - - [24/Jul/2025 20:41:41] "GET /_dash-component-suites/dash/dcc/dash_core_components-shared.v3_1_0m1753374100.js HTTP/1.1" 200 -
2025-07-24 20:41:41,846 | INFO | _internal.py:97 | 127.0.0.1 - - [24/Jul/2025 20:41:41] "GET /_dash-component-suites/dash_bootstrap_components/_components/dash_bootstrap_components.v1_6_0m1753376326.min.js HTTP/1.1" 200 -
2025-07-24 20:41:41,864 | INFO | _internal.py:97 | 127.0.0.1 - - [24/Jul/2025 20:41:41] "GET /_dash-component-suites/dash/dash-renderer/build/dash_renderer.v3_1_1m1753374100.min.js HTTP/1.1" 200 -
2025-07-24 20:41:41,877 | INFO | _internal.py:97 | 127.0.0.1 - - [24/Jul/2025 20:41:41] "GET /_dash-component-suites/dash/dash_table/bundle.v6_0_3m1753374100.js HTTP/1.1" 200 -
2025-07-24 20:41:41,921 | INFO | _internal.py:97 | 127.0.0.1 - - [24/Jul/2025 20:41:41] "GET /_dash-component-suites/dash/html/dash_html_components.v3_0_3m1753374100.min.js HTTP/1.1" 200 -
2025-07-24 20:41:41,927 | INFO | _internal.py:97 | 127.0.0.1 - - [24/Jul/2025 20:41:41] "GET /_dash-component-suites/dash/dcc/dash_core_components.v3_1_0m1753374100.js HTTP/1.1" 200 -
2025-07-24 20:41:43,110 | INFO | _internal.py:97 | 127.0.0.1 - - [24/Jul/2025 20:41:43] "GET /_dash-layout HTTP/1.1" 200 -
2025-07-24 20:41:43,112 | INFO | _internal.py:97 | 127.0.0.1 - - [24/Jul/2025 20:41:43] "GET /_dash-dependencies HTTP/1.1" 200 -
2025-07-24 20:41:43,117 | INFO | _internal.py:97 | 127.0.0.1 - - [24/Jul/2025 20:41:43] "GET /_favicon.ico?v=3.1.1 HTTP/1.1" 200 -
2025-07-24 20:41:43,146 | INFO | _internal.py:97 | 127.0.0.1 - - [24/Jul/2025 20:41:43] "POST /_dash-update-component HTTP/1.1" 200 -
2025-07-24 20:41:43,504 | INFO | _internal.py:97 | 127.0.0.1 - - [24/Jul/2025 20:41:43] "GET /_favicon.ico?v=3.1.1 HTTP/1.1" 200 -
2025-07-24 20:42:04,880 | INFO | _internal.py:97 | 192.168.1.80 - - [24/Jul/2025 20:42:04] "GET / HTTP/1.1" 200 -
2025-07-24 20:42:04,924 | INFO | _internal.py:97 | 192.168.1.80 - - [24/Jul/2025 20:42:04] "GET /_dash-component-suites/dash/deps/polyfill@7.v3_1_1m1753374100.12.1.min.js HTTP/1.1" 200 -
2025-07-24 20:42:04,931 | INFO | _internal.py:97 | 192.168.1.80 - - [24/Jul/2025 20:42:04] "GET /_dash-component-suites/dash/deps/react-dom@18.v3_1_1m1753374100.3.1.min.js HTTP/1.1" 200 -
2025-07-24 20:42:04,933 | INFO | _internal.py:97 | 192.168.1.80 - - [24/Jul/2025 20:42:04] "GET /_dash-component-suites/dash/deps/react@18.v3_1_1m1753374100.3.1.min.js HTTP/1.1" 200 -
2025-07-24 20:42:04,935 | INFO | _internal.py:97 | 192.168.1.80 - - [24/Jul/2025 20:42:04] "GET /_dash-component-suites/dash_bootstrap_components/_components/dash_bootstrap_components.v1_6_0m1753376326.min.js HTTP/1.1" 200 -
2025-07-24 20:42:04,935 | INFO | _internal.py:97 | 192.168.1.80 - - [24/Jul/2025 20:42:04] "GET /_dash-component-suites/dash/deps/prop-types@15.v3_1_1m1753374100.8.1.min.js HTTP/1.1" 200 -
2025-07-24 20:42:04,936 | INFO | _internal.py:97 | 192.168.1.80 - - [24/Jul/2025 20:42:04] "GET /_dash-component-suites/dash/dcc/dash_core_components.v3_1_0m1753374100.js HTTP/1.1" 200 -
2025-07-24 20:42:04,936 | INFO | _internal.py:97 | 192.168.1.80 - - [24/Jul/2025 20:42:04] "GET /_dash-component-suites/dash/dash-renderer/build/dash_renderer.v3_1_1m1753374100.min.js HTTP/1.1" 200 -
2025-07-24 20:42:04,943 | INFO | _internal.py:97 | 192.168.1.80 - - [24/Jul/2025 20:42:04] "GET /_dash-component-suites/dash/dcc/dash_core_components-shared.v3_1_0m1753374100.js HTTP/1.1" 200 -
2025-07-24 20:42:04,951 | INFO | _internal.py:97 | 192.168.1.80 - - [24/Jul/2025 20:42:04] "GET /_dash-component-suites/dash/html/dash_html_components.v3_0_3m1753374100.min.js HTTP/1.1" 200 -
2025-07-24 20:42:04,955 | INFO | _internal.py:97 | 192.168.1.80 - - [24/Jul/2025 20:42:04] "GET /_dash-component-suites/dash/dash_table/bundle.v6_0_3m1753374100.js HTTP/1.1" 200 -
2025-07-24 20:42:06,556 | INFO | _internal.py:97 | 192.168.1.80 - - [24/Jul/2025 20:42:06] "GET /_favicon.ico?v=3.1.1 HTTP/1.1" 200 -
2025-07-24 20:42:06,563 | INFO | _internal.py:97 | 192.168.1.80 - - [24/Jul/2025 20:42:06] "GET /_dash-layout HTTP/1.1" 200 -
2025-07-24 20:42:06,565 | INFO | _internal.py:97 | 192.168.1.80 - - [24/Jul/2025 20:42:06] "GET /_dash-dependencies HTTP/1.1" 200 -
2025-07-24 20:42:06,592 | INFO | _internal.py:97 | 192.168.1.80 - - [24/Jul/2025 20:42:06] "POST /_dash-update-component HTTP/1.1" 200 -
2025-07-24 20:42:07,190 | INFO | _internal.py:97 | 192.168.1.80 - - [24/Jul/2025 20:42:07] "GET /_favicon.ico?v=3.1.1 HTTP/1.1" 200 -
2025-07-24 20:42:13,661 | INFO | _internal.py:97 | 192.168.1.80 - - [24/Jul/2025 20:42:13] "POST /_dash-update-component HTTP/1.1" 200 -
2025-07-24 20:42:15,435 | INFO | _internal.py:97 | 192.168.1.80 - - [24/Jul/2025 20:42:15] "POST /_dash-update-component HTTP/1.1" 200 -
2025-07-24 20:42:15,453 | INFO | _internal.py:97 | 192.168.1.80 - - [24/Jul/2025 20:42:15] "POST /_dash-update-component HTTP/1.1" 200 -
2025-07-24 20:42:15,496 | INFO | _internal.py:97 | 192.168.1.80 - - [24/Jul/2025 20:42:15] "GET /_dash-component-suites/dash/dcc/async-dropdown.js HTTP/1.1" 200 -
2025-07-24 20:42:19,905 | INFO | _internal.py:97 | 192.168.1.80 - - [24/Jul/2025 20:42:19] "POST /_dash-update-component HTTP/1.1" 200 -
2025-07-24 20:46:27,750 | WARNING | vpn_manager.py:31 | No working VPN server found!
2025-07-24 20:51:27,749 | WARNING | vpn_manager.py:31 | No working VPN server found!
2025-07-24 20:56:27,749 | WARNING | vpn_manager.py:31 | No working VPN server found!
2025-07-24 21:01:27,750 | WARNING | vpn_manager.py:31 | No working VPN server found!
2025-07-24 21:06:27,750 | WARNING | vpn_manager.py:31 | No working VPN server found!
2025-07-24 21:11:27,750 | WARNING | vpn_manager.py:31 | No working VPN server found!
2025-07-24 21:21:19,440 | DEBUG | connectionpool.py:1049 | Starting new HTTPS connection (1): example.com:443
2025-07-24 21:21:20,543 | DEBUG | connectionpool.py:544 | https://example.com:443 "GET /subscription.txt HTTP/1.1" 404 1256
2025-07-24 21:21:20,545 | INFO | vpn_manager.py:22 | Fetched 0 VPN servers
2025-07-24 21:21:20,591 | DEBUG | proactor_events.py:633 | Using proactor: IocpProactor
2025-07-24 21:21:20,676 | INFO | dash.py:2340 | Dash is running on http://0.0.0.0:8050/

2025-07-24 21:21:21,582 | INFO | _internal.py:97 | [31m[1mWARNING: This is a development server. Do not use it in a production deployment. Use a production WSGI server instead.[0m
 * Running on all addresses (0.0.0.0)
 * Running on http://127.0.0.1:8050
 * Running on http://192.168.1.80:8050
2025-07-24 21:21:21,584 | INFO | _internal.py:97 | [33mPress CTRL+C to quit[0m
2025-07-24 21:21:28,259 | INFO | _internal.py:97 | 127.0.0.1 - - [24/Jul/2025 21:21:28] "GET / HTTP/1.1" 200 -
2025-07-24 21:21:28,647 | INFO | _internal.py:97 | 127.0.0.1 - - [24/Jul/2025 21:21:28] "GET /_favicon.ico?v=3.1.1 HTTP/1.1" 200 -
2025-07-24 21:21:28,673 | INFO | _internal.py:97 | 127.0.0.1 - - [24/Jul/2025 21:21:28] "GET /_dash-layout HTTP/1.1" 200 -
2025-07-24 21:21:28,675 | INFO | _internal.py:97 | 127.0.0.1 - - [24/Jul/2025 21:21:28] "GET /_dash-dependencies HTTP/1.1" 200 -
2025-07-24 21:21:28,764 | INFO | _internal.py:97 | 127.0.0.1 - - [24/Jul/2025 21:21:28] "GET /_favicon.ico?v=3.1.1 HTTP/1.1" 200 -
2025-07-24 21:21:28,769 | INFO | _internal.py:97 | 127.0.0.1 - - [24/Jul/2025 21:21:28] "POST /_dash-update-component HTTP/1.1" 200 -
2025-07-24 21:21:34,543 | INFO | _internal.py:97 | 192.168.1.80 - - [24/Jul/2025 21:21:34] "GET /vpn HTTP/1.1" 200 -
2025-07-24 21:21:34,939 | INFO | _internal.py:97 | 192.168.1.80 - - [24/Jul/2025 21:21:34] "GET /_favicon.ico?v=3.1.1 HTTP/1.1" 200 -
2025-07-24 21:21:34,954 | INFO | _internal.py:97 | 192.168.1.80 - - [24/Jul/2025 21:21:34] "GET /_dash-layout HTTP/1.1" 200 -
2025-07-24 21:21:34,954 | INFO | _internal.py:97 | 192.168.1.80 - - [24/Jul/2025 21:21:34] "GET /_dash-dependencies HTTP/1.1" 200 -
2025-07-24 21:21:35,042 | INFO | _internal.py:97 | 192.168.1.80 - - [24/Jul/2025 21:21:35] "GET /_favicon.ico?v=3.1.1 HTTP/1.1" 200 -
2025-07-24 21:21:35,048 | INFO | _internal.py:97 | 192.168.1.80 - - [24/Jul/2025 21:21:35] "POST /_dash-update-component HTTP/1.1" 200 -
2025-07-24 21:21:40,678 | INFO | _internal.py:97 | 127.0.0.1 - - [24/Jul/2025 21:21:40] "POST /_dash-update-component HTTP/1.1" 200 -
2025-07-24 21:21:40,691 | INFO | _internal.py:97 | 127.0.0.1 - - [24/Jul/2025 21:21:40] "GET /_dash-component-suites/dash/dcc/async-dropdown.js HTTP/1.1" 200 -
2025-07-24 21:21:40,695 | INFO | _internal.py:97 | 127.0.0.1 - - [24/Jul/2025 21:21:40] "[35m[1mPOST /_dash-update-component HTTP/1.1[0m" 204 -
2025-07-24 21:21:42,774 | DEBUG | exchange.py:542 | GET https://testnet.binance.vision/api/v3/exchangeInfo, Request: {'User-Agent': 'python-requests/2.32.4', 'Accept-Encoding': 'gzip, deflate', 'Accept': '*/*', 'Connection': 'keep-alive'} None
2025-07-24 21:21:42,775 | DEBUG | connectionpool.py:1049 | Starting new HTTPS connection (1): testnet.binance.vision:443
2025-07-24 21:21:45,974 | INFO | _internal.py:97 | 127.0.0.1 - - [24/Jul/2025 21:21:45] "POST /_dash-update-component HTTP/1.1" 200 -
2025-07-24 21:21:46,766 | ERROR | app.py:875 | Exception on /_dash-update-component [POST]
Traceback (most recent call last):
  File "D:\AI\AI_Trading_System_ki\venv\Lib\site-packages\urllib3\connectionpool.py", line 787, in urlopen
    response = self._make_request(
               ^^^^^^^^^^^^^^^^^^^
  File "D:\AI\AI_Trading_System_ki\venv\Lib\site-packages\urllib3\connectionpool.py", line 488, in _make_request
    raise new_e
  File "D:\AI\AI_Trading_System_ki\venv\Lib\site-packages\urllib3\connectionpool.py", line 464, in _make_request
    self._validate_conn(conn)
  File "D:\AI\AI_Trading_System_ki\venv\Lib\site-packages\urllib3\connectionpool.py", line 1093, in _validate_conn
    conn.connect()
  File "D:\AI\AI_Trading_System_ki\venv\Lib\site-packages\urllib3\connection.py", line 790, in connect
    sock_and_verified = _ssl_wrap_socket_and_match_hostname(
                        ^^^^^^^^^^^^^^^^^^^^^^^^^^^^^^^^^^^^
  File "D:\AI\AI_Trading_System_ki\venv\Lib\site-packages\urllib3\connection.py", line 969, in _ssl_wrap_socket_and_match_hostname
    ssl_sock = ssl_wrap_socket(
               ^^^^^^^^^^^^^^^^
  File "D:\AI\AI_Trading_System_ki\venv\Lib\site-packages\urllib3\util\ssl_.py", line 480, in ssl_wrap_socket
    ssl_sock = _ssl_wrap_socket_impl(sock, context, tls_in_tls, server_hostname)
               ^^^^^^^^^^^^^^^^^^^^^^^^^^^^^^^^^^^^^^^^^^^^^^^^^^^^^^^^^^^^^^^^^
  File "D:\AI\AI_Trading_System_ki\venv\Lib\site-packages\urllib3\util\ssl_.py", line 524, in _ssl_wrap_socket_impl
    return ssl_context.wrap_socket(sock, server_hostname=server_hostname)
           ^^^^^^^^^^^^^^^^^^^^^^^^^^^^^^^^^^^^^^^^^^^^^^^^^^^^^^^^^^^^^^
  File "C:\Users\CHH-074-32231030\AppData\Local\Programs\Python\Python311\Lib\ssl.py", line 517, in wrap_socket
    return self.sslsocket_class._create(
           ^^^^^^^^^^^^^^^^^^^^^^^^^^^^^
  File "C:\Users\CHH-074-32231030\AppData\Local\Programs\Python\Python311\Lib\ssl.py", line 1108, in _create
    self.do_handshake()
  File "C:\Users\CHH-074-32231030\AppData\Local\Programs\Python\Python311\Lib\ssl.py", line 1383, in do_handshake
    self._sslobj.do_handshake()
ConnectionResetError: [WinError 10054] An existing connection was forcibly closed by the remote host

During handling of the above exception, another exception occurred:

Traceback (most recent call last):
  File "D:\AI\AI_Trading_System_ki\venv\Lib\site-packages\requests\adapters.py", line 667, in send
    resp = conn.urlopen(
           ^^^^^^^^^^^^^
  File "D:\AI\AI_Trading_System_ki\venv\Lib\site-packages\urllib3\connectionpool.py", line 841, in urlopen
    retries = retries.increment(
              ^^^^^^^^^^^^^^^^^^
  File "D:\AI\AI_Trading_System_ki\venv\Lib\site-packages\urllib3\util\retry.py", line 474, in increment
    raise reraise(type(error), error, _stacktrace)
          ^^^^^^^^^^^^^^^^^^^^^^^^^^^^^^^^^^^^^^^^
  File "D:\AI\AI_Trading_System_ki\venv\Lib\site-packages\urllib3\util\util.py", line 38, in reraise
    raise value.with_traceback(tb)
  File "D:\AI\AI_Trading_System_ki\venv\Lib\site-packages\urllib3\connectionpool.py", line 787, in urlopen
    response = self._make_request(
               ^^^^^^^^^^^^^^^^^^^
  File "D:\AI\AI_Trading_System_ki\venv\Lib\site-packages\urllib3\connectionpool.py", line 488, in _make_request
    raise new_e
  File "D:\AI\AI_Trading_System_ki\venv\Lib\site-packages\urllib3\connectionpool.py", line 464, in _make_request
    self._validate_conn(conn)
  File "D:\AI\AI_Trading_System_ki\venv\Lib\site-packages\urllib3\connectionpool.py", line 1093, in _validate_conn
    conn.connect()
  File "D:\AI\AI_Trading_System_ki\venv\Lib\site-packages\urllib3\connection.py", line 790, in connect
    sock_and_verified = _ssl_wrap_socket_and_match_hostname(
                        ^^^^^^^^^^^^^^^^^^^^^^^^^^^^^^^^^^^^
  File "D:\AI\AI_Trading_System_ki\venv\Lib\site-packages\urllib3\connection.py", line 969, in _ssl_wrap_socket_and_match_hostname
    ssl_sock = ssl_wrap_socket(
               ^^^^^^^^^^^^^^^^
  File "D:\AI\AI_Trading_System_ki\venv\Lib\site-packages\urllib3\util\ssl_.py", line 480, in ssl_wrap_socket
    ssl_sock = _ssl_wrap_socket_impl(sock, context, tls_in_tls, server_hostname)
               ^^^^^^^^^^^^^^^^^^^^^^^^^^^^^^^^^^^^^^^^^^^^^^^^^^^^^^^^^^^^^^^^^
  File "D:\AI\AI_Trading_System_ki\venv\Lib\site-packages\urllib3\util\ssl_.py", line 524, in _ssl_wrap_socket_impl
    return ssl_context.wrap_socket(sock, server_hostname=server_hostname)
           ^^^^^^^^^^^^^^^^^^^^^^^^^^^^^^^^^^^^^^^^^^^^^^^^^^^^^^^^^^^^^^
  File "C:\Users\CHH-074-32231030\AppData\Local\Programs\Python\Python311\Lib\ssl.py", line 517, in wrap_socket
    return self.sslsocket_class._create(
           ^^^^^^^^^^^^^^^^^^^^^^^^^^^^^
  File "C:\Users\CHH-074-32231030\AppData\Local\Programs\Python\Python311\Lib\ssl.py", line 1108, in _create
    self.do_handshake()
  File "C:\Users\CHH-074-32231030\AppData\Local\Programs\Python\Python311\Lib\ssl.py", line 1383, in do_handshake
    self._sslobj.do_handshake()
urllib3.exceptions.ProtocolError: ('Connection aborted.', ConnectionResetError(10054, 'An existing connection was forcibly closed by the remote host', None, 10054, None))

During handling of the above exception, another exception occurred:

Traceback (most recent call last):
  File "D:\AI\AI_Trading_System_ki\venv\Lib\site-packages\ccxt\base\exchange.py", line 556, in fetch
    response = self.session.request(
               ^^^^^^^^^^^^^^^^^^^^^
  File "D:\AI\AI_Trading_System_ki\venv\Lib\site-packages\requests\sessions.py", line 589, in request
    resp = self.send(prep, **send_kwargs)
           ^^^^^^^^^^^^^^^^^^^^^^^^^^^^^^
  File "D:\AI\AI_Trading_System_ki\venv\Lib\site-packages\requests\sessions.py", line 703, in send
    r = adapter.send(request, **kwargs)
        ^^^^^^^^^^^^^^^^^^^^^^^^^^^^^^^
  File "D:\AI\AI_Trading_System_ki\venv\Lib\site-packages\requests\adapters.py", line 682, in send
    raise ConnectionError(err, request=request)
requests.exceptions.ConnectionError: ('Connection aborted.', ConnectionResetError(10054, 'An existing connection was forcibly closed by the remote host', None, 10054, None))

The above exception was the direct cause of the following exception:

Traceback (most recent call last):
  File "D:\AI\AI_Trading_System_ki\venv\Lib\site-packages\flask\app.py", line 1511, in wsgi_app
    response = self.full_dispatch_request()
               ^^^^^^^^^^^^^^^^^^^^^^^^^^^^
  File "D:\AI\AI_Trading_System_ki\venv\Lib\site-packages\flask\app.py", line 919, in full_dispatch_request
    rv = self.handle_user_exception(e)
         ^^^^^^^^^^^^^^^^^^^^^^^^^^^^^
  File "D:\AI\AI_Trading_System_ki\venv\Lib\site-packages\flask\app.py", line 917, in full_dispatch_request
    rv = self.dispatch_request()
         ^^^^^^^^^^^^^^^^^^^^^^^
  File "D:\AI\AI_Trading_System_ki\venv\Lib\site-packages\flask\app.py", line 902, in dispatch_request
    return self.ensure_sync(self.view_functions[rule.endpoint])(**view_args)  # type: ignore[no-any-return]
           ^^^^^^^^^^^^^^^^^^^^^^^^^^^^^^^^^^^^^^^^^^^^^^^^^^^^^^^^^^^^^^^^^
  File "D:\AI\AI_Trading_System_ki\venv\Lib\site-packages\dash\dash.py", line 1484, in dispatch
    response_data = ctx.run(partial_func)
                    ^^^^^^^^^^^^^^^^^^^^^
  File "D:\AI\AI_Trading_System_ki\venv\Lib\site-packages\dash\_callback.py", line 698, in add_context
    raise err
  File "D:\AI\AI_Trading_System_ki\venv\Lib\site-packages\dash\_callback.py", line 689, in add_context
    output_value = _invoke_callback(func, *func_args, **func_kwargs)  # type: ignore[reportArgumentType]
                   ^^^^^^^^^^^^^^^^^^^^^^^^^^^^^^^^^^^^^^^^^^^^^^^^^
  File "D:\AI\AI_Trading_System_ki\venv\Lib\site-packages\dash\_callback.py", line 58, in _invoke_callback
    return func(*args, **kwargs)  # %% callback invoked %%
           ^^^^^^^^^^^^^^^^^^^^^
  File "D:\AI\AI_Trading_System_ki\ui\dashboard_main.py", line 65, in run_backtest
    stats = engine.run(pair, initial_cash=cash)
            ^^^^^^^^^^^^^^^^^^^^^^^^^^^^^^^^^^^
  File "D:\AI\AI_Trading_System_ki\core\backtester.py", line 30, in run
    df = self.fetch_ohlcv(symbol)
         ^^^^^^^^^^^^^^^^^^^^^^^^
  File "D:\AI\AI_Trading_System_ki\core\backtester.py", line 19, in fetch_ohlcv
    ohlcv = self.exchange.fetch_ohlcv(symbol, timeframe=timeframe, limit=limit)
            ^^^^^^^^^^^^^^^^^^^^^^^^^^^^^^^^^^^^^^^^^^^^^^^^^^^^^^^^^^^^^^^^^^^
  File "D:\AI\AI_Trading_System_ki\venv\Lib\site-packages\ccxt\binance.py", line 4447, in fetch_ohlcv
    self.load_markets()
  File "D:\AI\AI_Trading_System_ki\venv\Lib\site-packages\ccxt\base\exchange.py", line 1553, in load_markets
    markets = self.fetch_markets(params)
              ^^^^^^^^^^^^^^^^^^^^^^^^^^
  File "D:\AI\AI_Trading_System_ki\venv\Lib\site-packages\ccxt\binance.py", line 3041, in fetch_markets
    promisesRaw.append(self.publicGetExchangeInfo(params))
                       ^^^^^^^^^^^^^^^^^^^^^^^^^^^^^^^^^^
  File "D:\AI\AI_Trading_System_ki\venv\Lib\site-packages\ccxt\base\types.py", line 35, in unbound_method
    return _self.request(self.path, self.api, self.method, params, config=self.config)
           ^^^^^^^^^^^^^^^^^^^^^^^^^^^^^^^^^^^^^^^^^^^^^^^^^^^^^^^^^^^^^^^^^^^^^^^^^^^
  File "D:\AI\AI_Trading_System_ki\venv\Lib\site-packages\ccxt\binance.py", line 11338, in request
    response = self.fetch2(path, api, method, params, headers, body, config)
               ^^^^^^^^^^^^^^^^^^^^^^^^^^^^^^^^^^^^^^^^^^^^^^^^^^^^^^^^^^^^^
  File "D:\AI\AI_Trading_System_ki\venv\Lib\site-packages\ccxt\base\exchange.py", line 4525, in fetch2
    raise e
  File "D:\AI\AI_Trading_System_ki\venv\Lib\site-packages\ccxt\base\exchange.py", line 4516, in fetch2
    return self.fetch(request['url'], request['method'], request['headers'], request['body'])
           ^^^^^^^^^^^^^^^^^^^^^^^^^^^^^^^^^^^^^^^^^^^^^^^^^^^^^^^^^^^^^^^^^^^^^^^^^^^^^^^^^^
  File "D:\AI\AI_Trading_System_ki\venv\Lib\site-packages\ccxt\base\exchange.py", line 609, in fetch
    raise NetworkError(details) from e
ccxt.base.errors.NetworkError: binance GET https://testnet.binance.vision/api/v3/exchangeInfo
2025-07-24 21:21:46,908 | INFO | _internal.py:97 | 127.0.0.1 - - [24/Jul/2025 21:21:46] "POST /_dash-update-component HTTP/1.1" 200 -
2025-07-24 21:21:47,003 | INFO | _internal.py:97 | 127.0.0.1 - - [24/Jul/2025 21:21:47] "[35m[1mPOST /_dash-update-component HTTP/1.1[0m" 500 -
2025-07-24 21:21:48,991 | DEBUG | connectionpool.py:241 | Starting new HTTP connection (1): localhost:8000
2025-07-24 21:21:51,036 | DEBUG | connectionpool.py:544 | http://localhost:8000 "POST /retrain/strategy/rl/replay HTTP/1.1" 500 21
2025-07-24 21:21:51,059 | INFO | _internal.py:97 | 127.0.0.1 - - [24/Jul/2025 21:21:51] "POST /_dash-update-component HTTP/1.1" 200 -
2025-07-24 21:21:53,874 | DEBUG | connectionpool.py:241 | Starting new HTTP connection (1): localhost:8000
2025-07-24 21:21:55,913 | DEBUG | connectionpool.py:544 | http://localhost:8000 "POST /retrain/strategy/rl/train HTTP/1.1" 200 29
2025-07-24 21:21:55,915 | INFO | _internal.py:97 | 127.0.0.1 - - [24/Jul/2025 21:21:55] "POST /_dash-update-component HTTP/1.1" 200 -
2025-07-24 21:26:20,551 | WARNING | vpn_manager.py:31 | No working VPN server found!
2025-07-24 21:31:20,552 | WARNING | vpn_manager.py:31 | No working VPN server found!
2025-07-24 21:32:35,100 | INFO | _internal.py:97 | 127.0.0.1 - - [24/Jul/2025 21:32:35] "POST /_dash-update-component HTTP/1.1" 200 -
2025-07-24 21:36:20,554 | WARNING | vpn_manager.py:31 | No working VPN server found!
2025-07-24 21:41:20,554 | WARNING | vpn_manager.py:31 | No working VPN server found!
2025-07-24 21:46:20,554 | WARNING | vpn_manager.py:31 | No working VPN server found!
2025-07-24 21:51:20,556 | WARNING | vpn_manager.py:31 | No working VPN server found!
2025-07-24 21:56:20,556 | WARNING | vpn_manager.py:31 | No working VPN server found!
2025-07-24 22:01:20,557 | WARNING | vpn_manager.py:31 | No working VPN server found!
2025-07-24 22:06:20,557 | WARNING | vpn_manager.py:31 | No working VPN server found!
2025-07-24 22:11:20,558 | WARNING | vpn_manager.py:31 | No working VPN server found!
2025-07-24 22:16:20,560 | WARNING | vpn_manager.py:31 | No working VPN server found!
2025-07-24 22:21:20,561 | WARNING | vpn_manager.py:31 | No working VPN server found!
2025-07-24 22:26:20,562 | WARNING | vpn_manager.py:31 | No working VPN server found!
2025-07-24 22:31:20,563 | WARNING | vpn_manager.py:31 | No working VPN server found!
2025-07-24 22:36:20,563 | WARNING | vpn_manager.py:31 | No working VPN server found!
2025-07-24 22:41:20,563 | WARNING | vpn_manager.py:31 | No working VPN server found!
2025-07-24 22:46:20,563 | WARNING | vpn_manager.py:31 | No working VPN server found!
2025-07-24 22:51:20,564 | WARNING | vpn_manager.py:31 | No working VPN server found!
